<h3>Exception Generated On 05 अक्तूबर 2021 @ 00:13</h3><br /><br /><strong>Page Location:</strong> /api/product/delete/30035<br /><br /><strong>Client IP Address:</strong> 127.0.0.1<br /><br /><strong>Error Message:</strong> Error Deleting Product  : 
System.Reflection.TargetException: Non-static field requires a target.
   at System.Reflection.RtFieldInfo.CheckConsistency(Object target)
   at System.Reflection.RtFieldInfo.InternalGetValue(Object obj, StackCrawlMark& stackMark)
   at System.Reflection.RtFieldInfo.GetValue(Object obj)
   at System.Data.Entity.Core.Objects.ELinq.QueryParameterExpression.TryGetFieldOrPropertyValue(MemberExpression me, Object instance, Object& memberValue)
   at System.Data.Entity.Core.Objects.ELinq.QueryParameterExpression.TryEvaluatePath(Expression expression, ConstantExpression& constantExpression)
   at System.Data.Entity.Core.Objects.ELinq.QueryParameterExpression.EvaluateParameter(Object[] arguments)
   at System.Data.Entity.Core.Objects.ELinq.ELinqQueryState.GetExecutionPlan(Nullable`1 forMergeOption)
   at System.Data.Entity.Core.Objects.ObjectQuery`1.<>c__DisplayClass7.<GetResults>b__6()
   at System.Data.Entity.Core.Objects.ObjectContext.ExecuteInTransaction[T](Func`1 func, IDbExecutionStrategy executionStrategy, Boolean startLocalTransaction, Boolean releaseConnectionOnSuccess)
   at System.Data.Entity.Core.Objects.ObjectQuery`1.<>c__DisplayClass7.<GetResults>b__5()
   at System.Data.Entity.SqlServer.DefaultSqlExecutionStrategy.Execute[TResult](Func`1 operation)
   at System.Data.Entity.Core.Objects.ObjectQuery`1.GetResults(Nullable`1 forMergeOption)
   at System.Data.Entity.Core.Objects.ObjectQuery`1.<System.Collections.Generic.IEnumerable<T>.GetEnumerator>b__0()
   at System.Data.Entity.Internal.LazyEnumerator`1.MoveNext()
   at System.Linq.Enumerable.SingleOrDefault[TSource](IEnumerable`1 source)
   at System.Data.Entity.Core.Objects.ELinq.ObjectQueryProvider.<GetElementFunction>b__2[TResult](IEnumerable`1 sequence)
   at System.Data.Entity.Core.Objects.ELinq.ObjectQueryProvider.ExecuteSingle[TResult](IEnumerable`1 query, Expression queryRoot)
   at System.Data.Entity.Core.Objects.ELinq.ObjectQueryProvider.System.Linq.IQueryProvider.Execute[TResult](Expression expression)
   at System.Data.Entity.Internal.Linq.DbQueryProvider.Execute[TResult](Expression expression)
   at System.Linq.Queryable.SingleOrDefault[TSource](IQueryable`1 source)
   at XOG.AppCode.BLL.ProductBL.<DeleteAsync>d__10.MoveNext()<br /><br /><strong>Error Details:</strong> <br /><br /><strong>Method Name:</strong> <br /><br /><strong>Source:</strong> <br /><br /><strong>Stack Trace:</strong><br />NA<br /><hr /><br /><h3>Mail Exception</h3><br /><br /><strong>Error Message:</strong> The SMTP host was not specified.<br /><br /><strong>Error Details:</strong> <br /><br /><strong>Method Name:</strong> CheckHostAndPort<br /><br /><strong>Source:</strong> System<br /><br /><strong>Stack Trace:</strong><br />   at System.Net.Mail.SmtpClient.CheckHostAndPort()
   at System.Net.Mail.SmtpClient.Send(MailMessage message)
   at XOG.Helpers.MailHelper.SendUsingSmtp(IdentityMessage message)
   at XOG.Helpers.MailHelper.Send(IdentityMessage message)
   at XOG.Util.ErrorLogger.LogError(Exception ex, DbEntityValidationException e)<hr /><br />
<h3>Exception Generated On 05 अक्तूबर 2021 @ 00:13</h3><br /><br /><strong>Page Location:</strong> /api/product/delete/30035<br /><br /><strong>Client IP Address:</strong> 127.0.0.1<br /><br /><strong>Error Message:</strong> Error Deleting Product  : 
System.NullReferenceException: Object reference not set to an instance of an object.
   at XOG.AppCode.BLL.ProductBL.<DeleteAsync>d__10.MoveNext()<br /><br /><strong>Error Details:</strong> <br /><br /><strong>Method Name:</strong> <br /><br /><strong>Source:</strong> <br /><br /><strong>Stack Trace:</strong><br />NA<br /><hr /><br /><h3>Mail Exception</h3><br /><br /><strong>Error Message:</strong> The SMTP host was not specified.<br /><br /><strong>Error Details:</strong> <br /><br /><strong>Method Name:</strong> CheckHostAndPort<br /><br /><strong>Source:</strong> System<br /><br /><strong>Stack Trace:</strong><br />   at System.Net.Mail.SmtpClient.CheckHostAndPort()
   at System.Net.Mail.SmtpClient.Send(MailMessage message)
   at XOG.Helpers.MailHelper.SendUsingSmtp(IdentityMessage message)
   at XOG.Helpers.MailHelper.Send(IdentityMessage message)
   at XOG.Util.ErrorLogger.LogError(Exception ex, DbEntityValidationException e)<hr /><br />
<h3>Exception Generated On 05 अक्तूबर 2021 @ 23:41</h3><br /><br /><strong>Page Location:</strong> /api/productgroup/add<br /><br /><strong>Client IP Address:</strong> 127.0.0.1<br /><br /><strong>Error Message:</strong> Error Adding Product Group  : 
System.Data.Entity.Infrastructure.DbUpdateException: An error occurred while updating the entries. See the inner exception for details. ---> System.Data.Entity.Core.UpdateException: An error occurred while updating the entries. See the inner exception for details. ---> System.Data.SqlClient.SqlException: The INSERT statement conflicted with the FOREIGN KEY constraint "fk_ProductGroup_SubCategories". The conflict occurred in database "xog_db", table "dbo.SubCategories", column 'Id'.
The statement has been terminated.
   at System.Data.SqlClient.SqlCommand.<>c.<ExecuteDbDataReaderAsync>b__180_0(Task`1 result)
   at System.Threading.Tasks.ContinuationResultTaskFromResultTask`2.InnerInvoke()
   at System.Threading.Tasks.Task.Execute()
--- End of stack trace from previous location where exception was thrown ---
   at System.Runtime.CompilerServices.TaskAwaiter.ThrowForNonSuccess(Task task)
   at System.Runtime.CompilerServices.TaskAwaiter.HandleNonSuccessAndDebuggerNotification(Task task)
   at System.Data.Entity.Utilities.TaskExtensions.CultureAwaiter`1.GetResult()
   at System.Data.Entity.Core.Mapping.Update.Internal.DynamicUpdateCommand.<ExecuteAsync>d__0.MoveNext()
--- End of stack trace from previous location where exception was thrown ---
   at System.Runtime.CompilerServices.TaskAwaiter.ThrowForNonSuccess(Task task)
   at System.Runtime.CompilerServices.TaskAwaiter.HandleNonSuccessAndDebuggerNotification(Task task)
   at System.Data.Entity.Core.Mapping.Update.Internal.UpdateTranslator.<UpdateAsync>d__0.MoveNext()
   --- End of inner exception stack trace ---
   at System.Data.Entity.Core.Mapping.Update.Internal.UpdateTranslator.<UpdateAsync>d__0.MoveNext()
--- End of stack trace from previous location where exception was thrown ---
   at System.Runtime.CompilerServices.TaskAwaiter.ThrowForNonSuccess(Task task)
   at System.Runtime.CompilerServices.TaskAwaiter.HandleNonSuccessAndDebuggerNotification(Task task)
   at System.Data.Entity.Core.Objects.ObjectContext.<ExecuteInTransactionAsync>d__3d`1.MoveNext()
--- End of stack trace from previous location where exception was thrown ---
   at System.Runtime.CompilerServices.TaskAwaiter.ThrowForNonSuccess(Task task)
   at System.Runtime.CompilerServices.TaskAwaiter.HandleNonSuccessAndDebuggerNotification(Task task)
   at System.Data.Entity.Core.Objects.ObjectContext.<SaveChangesToStoreAsync>d__39.MoveNext()
--- End of stack trace from previous location where exception was thrown ---
   at System.Runtime.CompilerServices.TaskAwaiter.ThrowForNonSuccess(Task task)
   at System.Runtime.CompilerServices.TaskAwaiter.HandleNonSuccessAndDebuggerNotification(Task task)
   at System.Data.Entity.SqlServer.DefaultSqlExecutionStrategy.<ExecuteAsyncImplementation>d__9`1.MoveNext()
--- End of stack trace from previous location where exception was thrown ---
   at System.Runtime.CompilerServices.TaskAwaiter.ThrowForNonSuccess(Task task)
   at System.Runtime.CompilerServices.TaskAwaiter.HandleNonSuccessAndDebuggerNotification(Task task)
   at System.Data.Entity.Core.Objects.ObjectContext.<SaveChangesInternalAsync>d__31.MoveNext()
   --- End of inner exception stack trace ---
   at System.Runtime.CompilerServices.TaskAwaiter.ThrowForNonSuccess(Task task)
   at System.Runtime.CompilerServices.TaskAwaiter.HandleNonSuccessAndDebuggerNotification(Task task)
   at System.Runtime.CompilerServices.TaskAwaiter`1.GetResult()
   at XOG.AppCode.BLL.ProductGroupBL.<AddAsync>d__9.MoveNext() in D:\Projects\XOGProject\XOG.API\XOG.API\AppCode\BLL\ProductGroupBL.cs:line 182<br /><br /><strong>Error Details:</strong> <br /><br /><strong>Method Name:</strong> <br /><br /><strong>Source:</strong> <br /><br /><strong>Stack Trace:</strong><br />NA<br /><hr /><br /><h3>Mail Exception</h3><br /><br /><strong>Error Message:</strong> The SMTP host was not specified.<br /><br /><strong>Error Details:</strong> <br /><br /><strong>Method Name:</strong> CheckHostAndPort<br /><br /><strong>Source:</strong> System<br /><br /><strong>Stack Trace:</strong><br />   at System.Net.Mail.SmtpClient.CheckHostAndPort()
   at System.Net.Mail.SmtpClient.Send(MailMessage message)
   at XOG.Helpers.MailHelper.SendUsingSmtp(IdentityMessage message) in D:\Projects\XOGProject\XOG.API\XOG.API\AppCode\Helpers\MailHelper.cs:line 213
   at XOG.Helpers.MailHelper.Send(IdentityMessage message) in D:\Projects\XOGProject\XOG.API\XOG.API\AppCode\Helpers\MailHelper.cs:line 105
   at XOG.Util.ErrorLogger.LogError(Exception ex, DbEntityValidationException e) in D:\Projects\XOGProject\XOG.API\XOG.API\AppCode\Util\ErrorLogger.cs:line 24<hr /><br />
<h3>Exception Generated On 05 अक्तूबर 2021 @ 23:41</h3><br /><br /><strong>Page Location:</strong> /api/productgroup/add<br /><br /><strong>Client IP Address:</strong> 127.0.0.1<br /><br /><strong>Error Message:</strong> Error Adding Product Group  : 
System.Data.Entity.Infrastructure.DbUpdateException: An error occurred while updating the entries. See the inner exception for details. ---> System.Data.Entity.Core.UpdateException: An error occurred while updating the entries. See the inner exception for details. ---> System.Data.SqlClient.SqlException: The INSERT statement conflicted with the FOREIGN KEY constraint "fk_ProductGroup_SubCategories". The conflict occurred in database "xog_db", table "dbo.SubCategories", column 'Id'.
The statement has been terminated.
   at System.Data.SqlClient.SqlCommand.<>c.<ExecuteDbDataReaderAsync>b__180_0(Task`1 result)
   at System.Threading.Tasks.ContinuationResultTaskFromResultTask`2.InnerInvoke()
   at System.Threading.Tasks.Task.Execute()
--- End of stack trace from previous location where exception was thrown ---
   at System.Runtime.CompilerServices.TaskAwaiter.ThrowForNonSuccess(Task task)
   at System.Runtime.CompilerServices.TaskAwaiter.HandleNonSuccessAndDebuggerNotification(Task task)
   at System.Data.Entity.Utilities.TaskExtensions.CultureAwaiter`1.GetResult()
   at System.Data.Entity.Core.Mapping.Update.Internal.DynamicUpdateCommand.<ExecuteAsync>d__0.MoveNext()
--- End of stack trace from previous location where exception was thrown ---
   at System.Runtime.CompilerServices.TaskAwaiter.ThrowForNonSuccess(Task task)
   at System.Runtime.CompilerServices.TaskAwaiter.HandleNonSuccessAndDebuggerNotification(Task task)
   at System.Data.Entity.Core.Mapping.Update.Internal.UpdateTranslator.<UpdateAsync>d__0.MoveNext()
   --- End of inner exception stack trace ---
   at System.Data.Entity.Core.Mapping.Update.Internal.UpdateTranslator.<UpdateAsync>d__0.MoveNext()
--- End of stack trace from previous location where exception was thrown ---
   at System.Runtime.CompilerServices.TaskAwaiter.ThrowForNonSuccess(Task task)
   at System.Runtime.CompilerServices.TaskAwaiter.HandleNonSuccessAndDebuggerNotification(Task task)
   at System.Data.Entity.Core.Objects.ObjectContext.<ExecuteInTransactionAsync>d__3d`1.MoveNext()
--- End of stack trace from previous location where exception was thrown ---
   at System.Runtime.CompilerServices.TaskAwaiter.ThrowForNonSuccess(Task task)
   at System.Runtime.CompilerServices.TaskAwaiter.HandleNonSuccessAndDebuggerNotification(Task task)
   at System.Data.Entity.Core.Objects.ObjectContext.<SaveChangesToStoreAsync>d__39.MoveNext()
--- End of stack trace from previous location where exception was thrown ---
   at System.Runtime.CompilerServices.TaskAwaiter.ThrowForNonSuccess(Task task)
   at System.Runtime.CompilerServices.TaskAwaiter.HandleNonSuccessAndDebuggerNotification(Task task)
   at System.Data.Entity.SqlServer.DefaultSqlExecutionStrategy.<ExecuteAsyncImplementation>d__9`1.MoveNext()
--- End of stack trace from previous location where exception was thrown ---
   at System.Runtime.CompilerServices.TaskAwaiter.ThrowForNonSuccess(Task task)
   at System.Runtime.CompilerServices.TaskAwaiter.HandleNonSuccessAndDebuggerNotification(Task task)
   at System.Data.Entity.Core.Objects.ObjectContext.<SaveChangesInternalAsync>d__31.MoveNext()
   --- End of inner exception stack trace ---
   at System.Runtime.CompilerServices.TaskAwaiter.ThrowForNonSuccess(Task task)
   at System.Runtime.CompilerServices.TaskAwaiter.HandleNonSuccessAndDebuggerNotification(Task task)
   at System.Runtime.CompilerServices.TaskAwaiter`1.GetResult()
   at XOG.AppCode.BLL.ProductGroupBL.<AddAsync>d__9.MoveNext() in D:\Projects\XOGProject\XOG.API\XOG.API\AppCode\BLL\ProductGroupBL.cs:line 182<br /><br /><strong>Error Details:</strong> <br /><br /><strong>Method Name:</strong> <br /><br /><strong>Source:</strong> <br /><br /><strong>Stack Trace:</strong><br />NA<br /><hr /><br /><h3>Mail Exception</h3><br /><br /><strong>Error Message:</strong> The SMTP host was not specified.<br /><br /><strong>Error Details:</strong> <br /><br /><strong>Method Name:</strong> CheckHostAndPort<br /><br /><strong>Source:</strong> System<br /><br /><strong>Stack Trace:</strong><br />   at System.Net.Mail.SmtpClient.CheckHostAndPort()
   at System.Net.Mail.SmtpClient.Send(MailMessage message)
   at XOG.Helpers.MailHelper.SendUsingSmtp(IdentityMessage message) in D:\Projects\XOGProject\XOG.API\XOG.API\AppCode\Helpers\MailHelper.cs:line 213
   at XOG.Helpers.MailHelper.Send(IdentityMessage message) in D:\Projects\XOGProject\XOG.API\XOG.API\AppCode\Helpers\MailHelper.cs:line 105
   at XOG.Util.ErrorLogger.LogError(Exception ex, DbEntityValidationException e) in D:\Projects\XOGProject\XOG.API\XOG.API\AppCode\Util\ErrorLogger.cs:line 24<hr /><br />
<h3>Exception Generated On 05 अक्तूबर 2021 @ 23:41</h3><br /><br /><strong>Page Location:</strong> /api/productgroup/add<br /><br /><strong>Client IP Address:</strong> 127.0.0.1<br /><br /><strong>Error Message:</strong> Error Adding Product Group  : 
System.Data.Entity.Infrastructure.DbUpdateException: An error occurred while updating the entries. See the inner exception for details. ---> System.Data.Entity.Core.UpdateException: An error occurred while updating the entries. See the inner exception for details. ---> System.Data.SqlClient.SqlException: The INSERT statement conflicted with the FOREIGN KEY constraint "fk_ProductGroup_SubCategories". The conflict occurred in database "xog_db", table "dbo.SubCategories", column 'Id'.
The statement has been terminated.
   at System.Data.SqlClient.SqlCommand.<>c.<ExecuteDbDataReaderAsync>b__180_0(Task`1 result)
   at System.Threading.Tasks.ContinuationResultTaskFromResultTask`2.InnerInvoke()
   at System.Threading.Tasks.Task.Execute()
--- End of stack trace from previous location where exception was thrown ---
   at System.Runtime.CompilerServices.TaskAwaiter.ThrowForNonSuccess(Task task)
   at System.Runtime.CompilerServices.TaskAwaiter.HandleNonSuccessAndDebuggerNotification(Task task)
   at System.Data.Entity.Utilities.TaskExtensions.CultureAwaiter`1.GetResult()
   at System.Data.Entity.Core.Mapping.Update.Internal.DynamicUpdateCommand.<ExecuteAsync>d__0.MoveNext()
--- End of stack trace from previous location where exception was thrown ---
   at System.Runtime.CompilerServices.TaskAwaiter.ThrowForNonSuccess(Task task)
   at System.Runtime.CompilerServices.TaskAwaiter.HandleNonSuccessAndDebuggerNotification(Task task)
   at System.Data.Entity.Core.Mapping.Update.Internal.UpdateTranslator.<UpdateAsync>d__0.MoveNext()
   --- End of inner exception stack trace ---
   at System.Data.Entity.Core.Mapping.Update.Internal.UpdateTranslator.<UpdateAsync>d__0.MoveNext()
--- End of stack trace from previous location where exception was thrown ---
   at System.Runtime.CompilerServices.TaskAwaiter.ThrowForNonSuccess(Task task)
   at System.Runtime.CompilerServices.TaskAwaiter.HandleNonSuccessAndDebuggerNotification(Task task)
   at System.Data.Entity.Core.Objects.ObjectContext.<ExecuteInTransactionAsync>d__3d`1.MoveNext()
--- End of stack trace from previous location where exception was thrown ---
   at System.Runtime.CompilerServices.TaskAwaiter.ThrowForNonSuccess(Task task)
   at System.Runtime.CompilerServices.TaskAwaiter.HandleNonSuccessAndDebuggerNotification(Task task)
   at System.Data.Entity.Core.Objects.ObjectContext.<SaveChangesToStoreAsync>d__39.MoveNext()
--- End of stack trace from previous location where exception was thrown ---
   at System.Runtime.CompilerServices.TaskAwaiter.ThrowForNonSuccess(Task task)
   at System.Runtime.CompilerServices.TaskAwaiter.HandleNonSuccessAndDebuggerNotification(Task task)
   at System.Data.Entity.SqlServer.DefaultSqlExecutionStrategy.<ExecuteAsyncImplementation>d__9`1.MoveNext()
--- End of stack trace from previous location where exception was thrown ---
   at System.Runtime.CompilerServices.TaskAwaiter.ThrowForNonSuccess(Task task)
   at System.Runtime.CompilerServices.TaskAwaiter.HandleNonSuccessAndDebuggerNotification(Task task)
   at System.Data.Entity.Core.Objects.ObjectContext.<SaveChangesInternalAsync>d__31.MoveNext()
   --- End of inner exception stack trace ---
   at System.Runtime.CompilerServices.TaskAwaiter.ThrowForNonSuccess(Task task)
   at System.Runtime.CompilerServices.TaskAwaiter.HandleNonSuccessAndDebuggerNotification(Task task)
   at System.Runtime.CompilerServices.TaskAwaiter`1.GetResult()
   at XOG.AppCode.BLL.ProductGroupBL.<AddAsync>d__9.MoveNext() in D:\Projects\XOGProject\XOG.API\XOG.API\AppCode\BLL\ProductGroupBL.cs:line 182<br /><br /><strong>Error Details:</strong> <br /><br /><strong>Method Name:</strong> <br /><br /><strong>Source:</strong> <br /><br /><strong>Stack Trace:</strong><br />NA<br /><hr /><br /><h3>Mail Exception</h3><br /><br /><strong>Error Message:</strong> The SMTP host was not specified.<br /><br /><strong>Error Details:</strong> <br /><br /><strong>Method Name:</strong> CheckHostAndPort<br /><br /><strong>Source:</strong> System<br /><br /><strong>Stack Trace:</strong><br />   at System.Net.Mail.SmtpClient.CheckHostAndPort()
   at System.Net.Mail.SmtpClient.Send(MailMessage message)
   at XOG.Helpers.MailHelper.SendUsingSmtp(IdentityMessage message) in D:\Projects\XOGProject\XOG.API\XOG.API\AppCode\Helpers\MailHelper.cs:line 213
   at XOG.Helpers.MailHelper.Send(IdentityMessage message) in D:\Projects\XOGProject\XOG.API\XOG.API\AppCode\Helpers\MailHelper.cs:line 105
   at XOG.Util.ErrorLogger.LogError(Exception ex, DbEntityValidationException e) in D:\Projects\XOGProject\XOG.API\XOG.API\AppCode\Util\ErrorLogger.cs:line 24<hr /><br />
<h3>Exception Generated On 05 अक्तूबर 2021 @ 23:42</h3><br /><br /><strong>Page Location:</strong> /api/productgroup/add<br /><br /><strong>Client IP Address:</strong> 127.0.0.1<br /><br /><strong>Error Message:</strong> Error Adding Product Group  : 
System.Data.Entity.Infrastructure.DbUpdateException: An error occurred while updating the entries. See the inner exception for details. ---> System.Data.Entity.Core.UpdateException: An error occurred while updating the entries. See the inner exception for details. ---> System.Data.SqlClient.SqlException: The INSERT statement conflicted with the FOREIGN KEY constraint "fk_ProductGroup_SubCategories". The conflict occurred in database "xog_db", table "dbo.SubCategories", column 'Id'.
The statement has been terminated.
   at System.Data.SqlClient.SqlCommand.<>c.<ExecuteDbDataReaderAsync>b__180_0(Task`1 result)
   at System.Threading.Tasks.ContinuationResultTaskFromResultTask`2.InnerInvoke()
   at System.Threading.Tasks.Task.Execute()
--- End of stack trace from previous location where exception was thrown ---
   at System.Runtime.CompilerServices.TaskAwaiter.ThrowForNonSuccess(Task task)
   at System.Runtime.CompilerServices.TaskAwaiter.HandleNonSuccessAndDebuggerNotification(Task task)
   at System.Data.Entity.Utilities.TaskExtensions.CultureAwaiter`1.GetResult()
   at System.Data.Entity.Core.Mapping.Update.Internal.DynamicUpdateCommand.<ExecuteAsync>d__0.MoveNext()
--- End of stack trace from previous location where exception was thrown ---
   at System.Runtime.CompilerServices.TaskAwaiter.ThrowForNonSuccess(Task task)
   at System.Runtime.CompilerServices.TaskAwaiter.HandleNonSuccessAndDebuggerNotification(Task task)
   at System.Data.Entity.Core.Mapping.Update.Internal.UpdateTranslator.<UpdateAsync>d__0.MoveNext()
   --- End of inner exception stack trace ---
   at System.Data.Entity.Core.Mapping.Update.Internal.UpdateTranslator.<UpdateAsync>d__0.MoveNext()
--- End of stack trace from previous location where exception was thrown ---
   at System.Runtime.CompilerServices.TaskAwaiter.ThrowForNonSuccess(Task task)
   at System.Runtime.CompilerServices.TaskAwaiter.HandleNonSuccessAndDebuggerNotification(Task task)
   at System.Data.Entity.Core.Objects.ObjectContext.<ExecuteInTransactionAsync>d__3d`1.MoveNext()
--- End of stack trace from previous location where exception was thrown ---
   at System.Runtime.CompilerServices.TaskAwaiter.ThrowForNonSuccess(Task task)
   at System.Runtime.CompilerServices.TaskAwaiter.HandleNonSuccessAndDebuggerNotification(Task task)
   at System.Data.Entity.Core.Objects.ObjectContext.<SaveChangesToStoreAsync>d__39.MoveNext()
--- End of stack trace from previous location where exception was thrown ---
   at System.Runtime.CompilerServices.TaskAwaiter.ThrowForNonSuccess(Task task)
   at System.Runtime.CompilerServices.TaskAwaiter.HandleNonSuccessAndDebuggerNotification(Task task)
   at System.Data.Entity.SqlServer.DefaultSqlExecutionStrategy.<ExecuteAsyncImplementation>d__9`1.MoveNext()
--- End of stack trace from previous location where exception was thrown ---
   at System.Runtime.CompilerServices.TaskAwaiter.ThrowForNonSuccess(Task task)
   at System.Runtime.CompilerServices.TaskAwaiter.HandleNonSuccessAndDebuggerNotification(Task task)
   at System.Data.Entity.Core.Objects.ObjectContext.<SaveChangesInternalAsync>d__31.MoveNext()
   --- End of inner exception stack trace ---
   at System.Runtime.CompilerServices.TaskAwaiter.ThrowForNonSuccess(Task task)
   at System.Runtime.CompilerServices.TaskAwaiter.HandleNonSuccessAndDebuggerNotification(Task task)
   at System.Runtime.CompilerServices.TaskAwaiter`1.GetResult()
   at XOG.AppCode.BLL.ProductGroupBL.<AddAsync>d__9.MoveNext() in D:\Projects\XOGProject\XOG.API\XOG.API\AppCode\BLL\ProductGroupBL.cs:line 182<br /><br /><strong>Error Details:</strong> <br /><br /><strong>Method Name:</strong> <br /><br /><strong>Source:</strong> <br /><br /><strong>Stack Trace:</strong><br />NA<br /><hr /><br /><h3>Mail Exception</h3><br /><br /><strong>Error Message:</strong> The SMTP host was not specified.<br /><br /><strong>Error Details:</strong> <br /><br /><strong>Method Name:</strong> CheckHostAndPort<br /><br /><strong>Source:</strong> System<br /><br /><strong>Stack Trace:</strong><br />   at System.Net.Mail.SmtpClient.CheckHostAndPort()
   at System.Net.Mail.SmtpClient.Send(MailMessage message)
   at XOG.Helpers.MailHelper.SendUsingSmtp(IdentityMessage message) in D:\Projects\XOGProject\XOG.API\XOG.API\AppCode\Helpers\MailHelper.cs:line 213
   at XOG.Helpers.MailHelper.Send(IdentityMessage message) in D:\Projects\XOGProject\XOG.API\XOG.API\AppCode\Helpers\MailHelper.cs:line 105
   at XOG.Util.ErrorLogger.LogError(Exception ex, DbEntityValidationException e) in D:\Projects\XOGProject\XOG.API\XOG.API\AppCode\Util\ErrorLogger.cs:line 24<hr /><br />
<h3>Exception Generated On 05 अक्तूबर 2021 @ 23:42</h3><br /><br /><strong>Page Location:</strong> /api/productgroup/add<br /><br /><strong>Client IP Address:</strong> 127.0.0.1<br /><br /><strong>Error Message:</strong> Error Adding Product Group  : 
System.Data.Entity.Infrastructure.DbUpdateException: An error occurred while updating the entries. See the inner exception for details. ---> System.Data.Entity.Core.UpdateException: An error occurred while updating the entries. See the inner exception for details. ---> System.Data.SqlClient.SqlException: The INSERT statement conflicted with the FOREIGN KEY constraint "fk_ProductGroup_SubCategories". The conflict occurred in database "xog_db", table "dbo.SubCategories", column 'Id'.
The statement has been terminated.
   at System.Data.SqlClient.SqlCommand.<>c.<ExecuteDbDataReaderAsync>b__180_0(Task`1 result)
   at System.Threading.Tasks.ContinuationResultTaskFromResultTask`2.InnerInvoke()
   at System.Threading.Tasks.Task.Execute()
--- End of stack trace from previous location where exception was thrown ---
   at System.Runtime.CompilerServices.TaskAwaiter.ThrowForNonSuccess(Task task)
   at System.Runtime.CompilerServices.TaskAwaiter.HandleNonSuccessAndDebuggerNotification(Task task)
   at System.Data.Entity.Utilities.TaskExtensions.CultureAwaiter`1.GetResult()
   at System.Data.Entity.Core.Mapping.Update.Internal.DynamicUpdateCommand.<ExecuteAsync>d__0.MoveNext()
--- End of stack trace from previous location where exception was thrown ---
   at System.Runtime.CompilerServices.TaskAwaiter.ThrowForNonSuccess(Task task)
   at System.Runtime.CompilerServices.TaskAwaiter.HandleNonSuccessAndDebuggerNotification(Task task)
   at System.Data.Entity.Core.Mapping.Update.Internal.UpdateTranslator.<UpdateAsync>d__0.MoveNext()
   --- End of inner exception stack trace ---
   at System.Data.Entity.Core.Mapping.Update.Internal.UpdateTranslator.<UpdateAsync>d__0.MoveNext()
--- End of stack trace from previous location where exception was thrown ---
   at System.Runtime.CompilerServices.TaskAwaiter.ThrowForNonSuccess(Task task)
   at System.Runtime.CompilerServices.TaskAwaiter.HandleNonSuccessAndDebuggerNotification(Task task)
   at System.Data.Entity.Core.Objects.ObjectContext.<ExecuteInTransactionAsync>d__3d`1.MoveNext()
--- End of stack trace from previous location where exception was thrown ---
   at System.Runtime.CompilerServices.TaskAwaiter.ThrowForNonSuccess(Task task)
   at System.Runtime.CompilerServices.TaskAwaiter.HandleNonSuccessAndDebuggerNotification(Task task)
   at System.Data.Entity.Core.Objects.ObjectContext.<SaveChangesToStoreAsync>d__39.MoveNext()
--- End of stack trace from previous location where exception was thrown ---
   at System.Runtime.CompilerServices.TaskAwaiter.ThrowForNonSuccess(Task task)
   at System.Runtime.CompilerServices.TaskAwaiter.HandleNonSuccessAndDebuggerNotification(Task task)
   at System.Data.Entity.SqlServer.DefaultSqlExecutionStrategy.<ExecuteAsyncImplementation>d__9`1.MoveNext()
--- End of stack trace from previous location where exception was thrown ---
   at System.Runtime.CompilerServices.TaskAwaiter.ThrowForNonSuccess(Task task)
   at System.Runtime.CompilerServices.TaskAwaiter.HandleNonSuccessAndDebuggerNotification(Task task)
   at System.Data.Entity.Core.Objects.ObjectContext.<SaveChangesInternalAsync>d__31.MoveNext()
   --- End of inner exception stack trace ---
   at System.Runtime.CompilerServices.TaskAwaiter.ThrowForNonSuccess(Task task)
   at System.Runtime.CompilerServices.TaskAwaiter.HandleNonSuccessAndDebuggerNotification(Task task)
   at System.Runtime.CompilerServices.TaskAwaiter`1.GetResult()
   at XOG.AppCode.BLL.ProductGroupBL.<AddAsync>d__9.MoveNext() in D:\Projects\XOGProject\XOG.API\XOG.API\AppCode\BLL\ProductGroupBL.cs:line 182<br /><br /><strong>Error Details:</strong> <br /><br /><strong>Method Name:</strong> <br /><br /><strong>Source:</strong> <br /><br /><strong>Stack Trace:</strong><br />NA<br /><hr /><br /><h3>Mail Exception</h3><br /><br /><strong>Error Message:</strong> The SMTP host was not specified.<br /><br /><strong>Error Details:</strong> <br /><br /><strong>Method Name:</strong> CheckHostAndPort<br /><br /><strong>Source:</strong> System<br /><br /><strong>Stack Trace:</strong><br />   at System.Net.Mail.SmtpClient.CheckHostAndPort()
   at System.Net.Mail.SmtpClient.Send(MailMessage message)
   at XOG.Helpers.MailHelper.SendUsingSmtp(IdentityMessage message) in D:\Projects\XOGProject\XOG.API\XOG.API\AppCode\Helpers\MailHelper.cs:line 213
   at XOG.Helpers.MailHelper.Send(IdentityMessage message) in D:\Projects\XOGProject\XOG.API\XOG.API\AppCode\Helpers\MailHelper.cs:line 105
   at XOG.Util.ErrorLogger.LogError(Exception ex, DbEntityValidationException e) in D:\Projects\XOGProject\XOG.API\XOG.API\AppCode\Util\ErrorLogger.cs:line 24<hr /><br />
<h3>Exception Generated On 05 अक्तूबर 2021 @ 23:44</h3><br /><br /><strong>Page Location:</strong> /api/productgroup/add<br /><br /><strong>Client IP Address:</strong> 127.0.0.1<br /><br /><strong>Error Message:</strong> Error Adding Product Group  : 
System.Data.Entity.Infrastructure.DbUpdateException: An error occurred while updating the entries. See the inner exception for details. ---> System.Data.Entity.Core.UpdateException: An error occurred while updating the entries. See the inner exception for details. ---> System.Data.SqlClient.SqlException: The INSERT statement conflicted with the FOREIGN KEY constraint "fk_ProductGroup_SubCategories". The conflict occurred in database "xog_db", table "dbo.SubCategories", column 'Id'.
The statement has been terminated.
   at System.Data.SqlClient.SqlCommand.<>c.<ExecuteDbDataReaderAsync>b__180_0(Task`1 result)
   at System.Threading.Tasks.ContinuationResultTaskFromResultTask`2.InnerInvoke()
   at System.Threading.Tasks.Task.Execute()
--- End of stack trace from previous location where exception was thrown ---
   at System.Runtime.CompilerServices.TaskAwaiter.ThrowForNonSuccess(Task task)
   at System.Runtime.CompilerServices.TaskAwaiter.HandleNonSuccessAndDebuggerNotification(Task task)
   at System.Data.Entity.Utilities.TaskExtensions.CultureAwaiter`1.GetResult()
   at System.Data.Entity.Core.Mapping.Update.Internal.DynamicUpdateCommand.<ExecuteAsync>d__0.MoveNext()
--- End of stack trace from previous location where exception was thrown ---
   at System.Runtime.CompilerServices.TaskAwaiter.ThrowForNonSuccess(Task task)
   at System.Runtime.CompilerServices.TaskAwaiter.HandleNonSuccessAndDebuggerNotification(Task task)
   at System.Data.Entity.Core.Mapping.Update.Internal.UpdateTranslator.<UpdateAsync>d__0.MoveNext()
   --- End of inner exception stack trace ---
   at System.Data.Entity.Core.Mapping.Update.Internal.UpdateTranslator.<UpdateAsync>d__0.MoveNext()
--- End of stack trace from previous location where exception was thrown ---
   at System.Runtime.CompilerServices.TaskAwaiter.ThrowForNonSuccess(Task task)
   at System.Runtime.CompilerServices.TaskAwaiter.HandleNonSuccessAndDebuggerNotification(Task task)
   at System.Data.Entity.Core.Objects.ObjectContext.<ExecuteInTransactionAsync>d__3d`1.MoveNext()
--- End of stack trace from previous location where exception was thrown ---
   at System.Runtime.CompilerServices.TaskAwaiter.ThrowForNonSuccess(Task task)
   at System.Runtime.CompilerServices.TaskAwaiter.HandleNonSuccessAndDebuggerNotification(Task task)
   at System.Data.Entity.Core.Objects.ObjectContext.<SaveChangesToStoreAsync>d__39.MoveNext()
--- End of stack trace from previous location where exception was thrown ---
   at System.Runtime.CompilerServices.TaskAwaiter.ThrowForNonSuccess(Task task)
   at System.Runtime.CompilerServices.TaskAwaiter.HandleNonSuccessAndDebuggerNotification(Task task)
   at System.Data.Entity.SqlServer.DefaultSqlExecutionStrategy.<ExecuteAsyncImplementation>d__9`1.MoveNext()
--- End of stack trace from previous location where exception was thrown ---
   at System.Runtime.CompilerServices.TaskAwaiter.ThrowForNonSuccess(Task task)
   at System.Runtime.CompilerServices.TaskAwaiter.HandleNonSuccessAndDebuggerNotification(Task task)
   at System.Data.Entity.Core.Objects.ObjectContext.<SaveChangesInternalAsync>d__31.MoveNext()
   --- End of inner exception stack trace ---
   at System.Runtime.CompilerServices.TaskAwaiter.ThrowForNonSuccess(Task task)
   at System.Runtime.CompilerServices.TaskAwaiter.HandleNonSuccessAndDebuggerNotification(Task task)
   at System.Runtime.CompilerServices.TaskAwaiter`1.GetResult()
   at XOG.AppCode.BLL.ProductGroupBL.<AddAsync>d__9.MoveNext() in D:\Projects\XOGProject\XOG.API\XOG.API\AppCode\BLL\ProductGroupBL.cs:line 182<br /><br /><strong>Error Details:</strong> <br /><br /><strong>Method Name:</strong> <br /><br /><strong>Source:</strong> <br /><br /><strong>Stack Trace:</strong><br />NA<br /><hr /><br /><h3>Mail Exception</h3><br /><br /><strong>Error Message:</strong> The SMTP host was not specified.<br /><br /><strong>Error Details:</strong> <br /><br /><strong>Method Name:</strong> CheckHostAndPort<br /><br /><strong>Source:</strong> System<br /><br /><strong>Stack Trace:</strong><br />   at System.Net.Mail.SmtpClient.CheckHostAndPort()
   at System.Net.Mail.SmtpClient.Send(MailMessage message)
   at XOG.Helpers.MailHelper.SendUsingSmtp(IdentityMessage message) in D:\Projects\XOGProject\XOG.API\XOG.API\AppCode\Helpers\MailHelper.cs:line 213
   at XOG.Helpers.MailHelper.Send(IdentityMessage message) in D:\Projects\XOGProject\XOG.API\XOG.API\AppCode\Helpers\MailHelper.cs:line 105
   at XOG.Util.ErrorLogger.LogError(Exception ex, DbEntityValidationException e) in D:\Projects\XOGProject\XOG.API\XOG.API\AppCode\Util\ErrorLogger.cs:line 24<hr /><br />
<h3>Exception Generated On 05 अक्तूबर 2021 @ 23:44</h3><br /><br /><strong>Page Location:</strong> /api/productgroup/add<br /><br /><strong>Client IP Address:</strong> 127.0.0.1<br /><br /><strong>Error Message:</strong> Error Adding Product Group  : 
System.Data.Entity.Infrastructure.DbUpdateException: An error occurred while updating the entries. See the inner exception for details. ---> System.Data.Entity.Core.UpdateException: An error occurred while updating the entries. See the inner exception for details. ---> System.Data.SqlClient.SqlException: The INSERT statement conflicted with the FOREIGN KEY constraint "fk_ProductGroup_SubCategories". The conflict occurred in database "xog_db", table "dbo.SubCategories", column 'Id'.
The statement has been terminated.
   at System.Data.SqlClient.SqlCommand.<>c.<ExecuteDbDataReaderAsync>b__180_0(Task`1 result)
   at System.Threading.Tasks.ContinuationResultTaskFromResultTask`2.InnerInvoke()
   at System.Threading.Tasks.Task.Execute()
--- End of stack trace from previous location where exception was thrown ---
   at System.Runtime.CompilerServices.TaskAwaiter.ThrowForNonSuccess(Task task)
   at System.Runtime.CompilerServices.TaskAwaiter.HandleNonSuccessAndDebuggerNotification(Task task)
   at System.Data.Entity.Utilities.TaskExtensions.CultureAwaiter`1.GetResult()
   at System.Data.Entity.Core.Mapping.Update.Internal.DynamicUpdateCommand.<ExecuteAsync>d__0.MoveNext()
--- End of stack trace from previous location where exception was thrown ---
   at System.Runtime.CompilerServices.TaskAwaiter.ThrowForNonSuccess(Task task)
   at System.Runtime.CompilerServices.TaskAwaiter.HandleNonSuccessAndDebuggerNotification(Task task)
   at System.Data.Entity.Core.Mapping.Update.Internal.UpdateTranslator.<UpdateAsync>d__0.MoveNext()
   --- End of inner exception stack trace ---
   at System.Data.Entity.Core.Mapping.Update.Internal.UpdateTranslator.<UpdateAsync>d__0.MoveNext()
--- End of stack trace from previous location where exception was thrown ---
   at System.Runtime.CompilerServices.TaskAwaiter.ThrowForNonSuccess(Task task)
   at System.Runtime.CompilerServices.TaskAwaiter.HandleNonSuccessAndDebuggerNotification(Task task)
   at System.Data.Entity.Core.Objects.ObjectContext.<ExecuteInTransactionAsync>d__3d`1.MoveNext()
--- End of stack trace from previous location where exception was thrown ---
   at System.Runtime.CompilerServices.TaskAwaiter.ThrowForNonSuccess(Task task)
   at System.Runtime.CompilerServices.TaskAwaiter.HandleNonSuccessAndDebuggerNotification(Task task)
   at System.Data.Entity.Core.Objects.ObjectContext.<SaveChangesToStoreAsync>d__39.MoveNext()
--- End of stack trace from previous location where exception was thrown ---
   at System.Runtime.CompilerServices.TaskAwaiter.ThrowForNonSuccess(Task task)
   at System.Runtime.CompilerServices.TaskAwaiter.HandleNonSuccessAndDebuggerNotification(Task task)
   at System.Data.Entity.SqlServer.DefaultSqlExecutionStrategy.<ExecuteAsyncImplementation>d__9`1.MoveNext()
--- End of stack trace from previous location where exception was thrown ---
   at System.Runtime.CompilerServices.TaskAwaiter.ThrowForNonSuccess(Task task)
   at System.Runtime.CompilerServices.TaskAwaiter.HandleNonSuccessAndDebuggerNotification(Task task)
   at System.Data.Entity.Core.Objects.ObjectContext.<SaveChangesInternalAsync>d__31.MoveNext()
   --- End of inner exception stack trace ---
   at System.Runtime.CompilerServices.TaskAwaiter.ThrowForNonSuccess(Task task)
   at System.Runtime.CompilerServices.TaskAwaiter.HandleNonSuccessAndDebuggerNotification(Task task)
   at System.Runtime.CompilerServices.TaskAwaiter`1.GetResult()
   at XOG.AppCode.BLL.ProductGroupBL.<AddAsync>d__9.MoveNext() in D:\Projects\XOGProject\XOG.API\XOG.API\AppCode\BLL\ProductGroupBL.cs:line 182<br /><br /><strong>Error Details:</strong> <br /><br /><strong>Method Name:</strong> <br /><br /><strong>Source:</strong> <br /><br /><strong>Stack Trace:</strong><br />NA<br /><hr /><br /><h3>Mail Exception</h3><br /><br /><strong>Error Message:</strong> The SMTP host was not specified.<br /><br /><strong>Error Details:</strong> <br /><br /><strong>Method Name:</strong> CheckHostAndPort<br /><br /><strong>Source:</strong> System<br /><br /><strong>Stack Trace:</strong><br />   at System.Net.Mail.SmtpClient.CheckHostAndPort()
   at System.Net.Mail.SmtpClient.Send(MailMessage message)
   at XOG.Helpers.MailHelper.SendUsingSmtp(IdentityMessage message) in D:\Projects\XOGProject\XOG.API\XOG.API\AppCode\Helpers\MailHelper.cs:line 213
   at XOG.Helpers.MailHelper.Send(IdentityMessage message) in D:\Projects\XOGProject\XOG.API\XOG.API\AppCode\Helpers\MailHelper.cs:line 105
   at XOG.Util.ErrorLogger.LogError(Exception ex, DbEntityValidationException e) in D:\Projects\XOGProject\XOG.API\XOG.API\AppCode\Util\ErrorLogger.cs:line 24<hr /><br />
<h3>Exception Generated On 05 अक्तूबर 2021 @ 23:45</h3><br /><br /><strong>Page Location:</strong> /api/subcategory/add<br /><br /><strong>Client IP Address:</strong> 127.0.0.1<br /><br /><strong>Error Message:</strong> Error Adding Sub Category  : 
System.Data.Entity.Infrastructure.DbUpdateException: An error occurred while updating the entries. See the inner exception for details. ---> System.Data.Entity.Core.UpdateException: An error occurred while updating the entries. See the inner exception for details. ---> System.Data.SqlClient.SqlException: The INSERT statement conflicted with the FOREIGN KEY constraint "fk_SubCategory_Category". The conflict occurred in database "xog_db", table "dbo.Categories", column 'Id'.
The statement has been terminated.
   at System.Data.SqlClient.SqlCommand.<>c.<ExecuteDbDataReaderAsync>b__180_0(Task`1 result)
   at System.Threading.Tasks.ContinuationResultTaskFromResultTask`2.InnerInvoke()
   at System.Threading.Tasks.Task.Execute()
--- End of stack trace from previous location where exception was thrown ---
   at System.Runtime.CompilerServices.TaskAwaiter.ThrowForNonSuccess(Task task)
   at System.Runtime.CompilerServices.TaskAwaiter.HandleNonSuccessAndDebuggerNotification(Task task)
   at System.Data.Entity.Utilities.TaskExtensions.CultureAwaiter`1.GetResult()
   at System.Data.Entity.Core.Mapping.Update.Internal.DynamicUpdateCommand.<ExecuteAsync>d__0.MoveNext()
--- End of stack trace from previous location where exception was thrown ---
   at System.Runtime.CompilerServices.TaskAwaiter.ThrowForNonSuccess(Task task)
   at System.Runtime.CompilerServices.TaskAwaiter.HandleNonSuccessAndDebuggerNotification(Task task)
   at System.Data.Entity.Core.Mapping.Update.Internal.UpdateTranslator.<UpdateAsync>d__0.MoveNext()
   --- End of inner exception stack trace ---
   at System.Data.Entity.Core.Mapping.Update.Internal.UpdateTranslator.<UpdateAsync>d__0.MoveNext()
--- End of stack trace from previous location where exception was thrown ---
   at System.Runtime.CompilerServices.TaskAwaiter.ThrowForNonSuccess(Task task)
   at System.Runtime.CompilerServices.TaskAwaiter.HandleNonSuccessAndDebuggerNotification(Task task)
   at System.Data.Entity.Core.Objects.ObjectContext.<ExecuteInTransactionAsync>d__3d`1.MoveNext()
--- End of stack trace from previous location where exception was thrown ---
   at System.Runtime.CompilerServices.TaskAwaiter.ThrowForNonSuccess(Task task)
   at System.Runtime.CompilerServices.TaskAwaiter.HandleNonSuccessAndDebuggerNotification(Task task)
   at System.Data.Entity.Core.Objects.ObjectContext.<SaveChangesToStoreAsync>d__39.MoveNext()
--- End of stack trace from previous location where exception was thrown ---
   at System.Runtime.CompilerServices.TaskAwaiter.ThrowForNonSuccess(Task task)
   at System.Runtime.CompilerServices.TaskAwaiter.HandleNonSuccessAndDebuggerNotification(Task task)
   at System.Data.Entity.SqlServer.DefaultSqlExecutionStrategy.<ExecuteAsyncImplementation>d__9`1.MoveNext()
--- End of stack trace from previous location where exception was thrown ---
   at System.Runtime.CompilerServices.TaskAwaiter.ThrowForNonSuccess(Task task)
   at System.Runtime.CompilerServices.TaskAwaiter.HandleNonSuccessAndDebuggerNotification(Task task)
   at System.Data.Entity.Core.Objects.ObjectContext.<SaveChangesInternalAsync>d__31.MoveNext()
   --- End of inner exception stack trace ---
   at System.Runtime.CompilerServices.TaskAwaiter.ThrowForNonSuccess(Task task)
   at System.Runtime.CompilerServices.TaskAwaiter.HandleNonSuccessAndDebuggerNotification(Task task)
   at System.Runtime.CompilerServices.TaskAwaiter`1.GetResult()
   at XOG.AppCode.BLL.SubCategoryBL.<AddAsync>d__9.MoveNext() in D:\Projects\XOGProject\XOG.API\XOG.API\AppCode\BLL\SubCategoryBL.cs:line 182<br /><br /><strong>Error Details:</strong> <br /><br /><strong>Method Name:</strong> <br /><br /><strong>Source:</strong> <br /><br /><strong>Stack Trace:</strong><br />NA<br /><hr /><br /><h3>Mail Exception</h3><br /><br /><strong>Error Message:</strong> The SMTP host was not specified.<br /><br /><strong>Error Details:</strong> <br /><br /><strong>Method Name:</strong> CheckHostAndPort<br /><br /><strong>Source:</strong> System<br /><br /><strong>Stack Trace:</strong><br />   at System.Net.Mail.SmtpClient.CheckHostAndPort()
   at System.Net.Mail.SmtpClient.Send(MailMessage message)
   at XOG.Helpers.MailHelper.SendUsingSmtp(IdentityMessage message) in D:\Projects\XOGProject\XOG.API\XOG.API\AppCode\Helpers\MailHelper.cs:line 213
   at XOG.Helpers.MailHelper.Send(IdentityMessage message) in D:\Projects\XOGProject\XOG.API\XOG.API\AppCode\Helpers\MailHelper.cs:line 105
   at XOG.Util.ErrorLogger.LogError(Exception ex, DbEntityValidationException e) in D:\Projects\XOGProject\XOG.API\XOG.API\AppCode\Util\ErrorLogger.cs:line 24<hr /><br />
<h3>Exception Generated On 05 अक्तूबर 2021 @ 23:46</h3><br /><br /><strong>Page Location:</strong> /api/subcategory/add<br /><br /><strong>Client IP Address:</strong> 127.0.0.1<br /><br /><strong>Error Message:</strong> Error Adding Sub Category  : 
System.Data.Entity.Infrastructure.DbUpdateException: An error occurred while updating the entries. See the inner exception for details. ---> System.Data.Entity.Core.UpdateException: An error occurred while updating the entries. See the inner exception for details. ---> System.Data.SqlClient.SqlException: The INSERT statement conflicted with the FOREIGN KEY constraint "fk_SubCategory_Category". The conflict occurred in database "xog_db", table "dbo.Categories", column 'Id'.
The statement has been terminated.
   at System.Data.SqlClient.SqlCommand.<>c.<ExecuteDbDataReaderAsync>b__180_0(Task`1 result)
   at System.Threading.Tasks.ContinuationResultTaskFromResultTask`2.InnerInvoke()
   at System.Threading.Tasks.Task.Execute()
--- End of stack trace from previous location where exception was thrown ---
   at System.Runtime.CompilerServices.TaskAwaiter.ThrowForNonSuccess(Task task)
   at System.Runtime.CompilerServices.TaskAwaiter.HandleNonSuccessAndDebuggerNotification(Task task)
   at System.Data.Entity.Utilities.TaskExtensions.CultureAwaiter`1.GetResult()
   at System.Data.Entity.Core.Mapping.Update.Internal.DynamicUpdateCommand.<ExecuteAsync>d__0.MoveNext()
--- End of stack trace from previous location where exception was thrown ---
   at System.Runtime.CompilerServices.TaskAwaiter.ThrowForNonSuccess(Task task)
   at System.Runtime.CompilerServices.TaskAwaiter.HandleNonSuccessAndDebuggerNotification(Task task)
   at System.Data.Entity.Core.Mapping.Update.Internal.UpdateTranslator.<UpdateAsync>d__0.MoveNext()
   --- End of inner exception stack trace ---
   at System.Data.Entity.Core.Mapping.Update.Internal.UpdateTranslator.<UpdateAsync>d__0.MoveNext()
--- End of stack trace from previous location where exception was thrown ---
   at System.Runtime.CompilerServices.TaskAwaiter.ThrowForNonSuccess(Task task)
   at System.Runtime.CompilerServices.TaskAwaiter.HandleNonSuccessAndDebuggerNotification(Task task)
   at System.Data.Entity.Core.Objects.ObjectContext.<ExecuteInTransactionAsync>d__3d`1.MoveNext()
--- End of stack trace from previous location where exception was thrown ---
   at System.Runtime.CompilerServices.TaskAwaiter.ThrowForNonSuccess(Task task)
   at System.Runtime.CompilerServices.TaskAwaiter.HandleNonSuccessAndDebuggerNotification(Task task)
   at System.Data.Entity.Core.Objects.ObjectContext.<SaveChangesToStoreAsync>d__39.MoveNext()
--- End of stack trace from previous location where exception was thrown ---
   at System.Runtime.CompilerServices.TaskAwaiter.ThrowForNonSuccess(Task task)
   at System.Runtime.CompilerServices.TaskAwaiter.HandleNonSuccessAndDebuggerNotification(Task task)
   at System.Data.Entity.SqlServer.DefaultSqlExecutionStrategy.<ExecuteAsyncImplementation>d__9`1.MoveNext()
--- End of stack trace from previous location where exception was thrown ---
   at System.Runtime.CompilerServices.TaskAwaiter.ThrowForNonSuccess(Task task)
   at System.Runtime.CompilerServices.TaskAwaiter.HandleNonSuccessAndDebuggerNotification(Task task)
   at System.Data.Entity.Core.Objects.ObjectContext.<SaveChangesInternalAsync>d__31.MoveNext()
   --- End of inner exception stack trace ---
   at System.Runtime.CompilerServices.TaskAwaiter.ThrowForNonSuccess(Task task)
   at System.Runtime.CompilerServices.TaskAwaiter.HandleNonSuccessAndDebuggerNotification(Task task)
   at System.Runtime.CompilerServices.TaskAwaiter`1.GetResult()
   at XOG.AppCode.BLL.SubCategoryBL.<AddAsync>d__9.MoveNext() in D:\Projects\XOGProject\XOG.API\XOG.API\AppCode\BLL\SubCategoryBL.cs:line 182<br /><br /><strong>Error Details:</strong> <br /><br /><strong>Method Name:</strong> <br /><br /><strong>Source:</strong> <br /><br /><strong>Stack Trace:</strong><br />NA<br /><hr /><br /><h3>Mail Exception</h3><br /><br /><strong>Error Message:</strong> The SMTP host was not specified.<br /><br /><strong>Error Details:</strong> <br /><br /><strong>Method Name:</strong> CheckHostAndPort<br /><br /><strong>Source:</strong> System<br /><br /><strong>Stack Trace:</strong><br />   at System.Net.Mail.SmtpClient.CheckHostAndPort()
   at System.Net.Mail.SmtpClient.Send(MailMessage message)
   at XOG.Helpers.MailHelper.SendUsingSmtp(IdentityMessage message) in D:\Projects\XOGProject\XOG.API\XOG.API\AppCode\Helpers\MailHelper.cs:line 213
   at XOG.Helpers.MailHelper.Send(IdentityMessage message) in D:\Projects\XOGProject\XOG.API\XOG.API\AppCode\Helpers\MailHelper.cs:line 105
   at XOG.Util.ErrorLogger.LogError(Exception ex, DbEntityValidationException e) in D:\Projects\XOGProject\XOG.API\XOG.API\AppCode\Util\ErrorLogger.cs:line 24<hr /><br />
<h3>Exception Generated On 05 अक्तूबर 2021 @ 23:46</h3><br /><br /><strong>Page Location:</strong> /api/subcategory/add<br /><br /><strong>Client IP Address:</strong> 127.0.0.1<br /><br /><strong>Error Message:</strong> Error Adding Sub Category  : 
System.Data.Entity.Infrastructure.DbUpdateException: An error occurred while updating the entries. See the inner exception for details. ---> System.Data.Entity.Core.UpdateException: An error occurred while updating the entries. See the inner exception for details. ---> System.Data.SqlClient.SqlException: The INSERT statement conflicted with the FOREIGN KEY constraint "fk_SubCategory_Category". The conflict occurred in database "xog_db", table "dbo.Categories", column 'Id'.
The statement has been terminated.
   at System.Data.SqlClient.SqlCommand.<>c.<ExecuteDbDataReaderAsync>b__180_0(Task`1 result)
   at System.Threading.Tasks.ContinuationResultTaskFromResultTask`2.InnerInvoke()
   at System.Threading.Tasks.Task.Execute()
--- End of stack trace from previous location where exception was thrown ---
   at System.Runtime.CompilerServices.TaskAwaiter.ThrowForNonSuccess(Task task)
   at System.Runtime.CompilerServices.TaskAwaiter.HandleNonSuccessAndDebuggerNotification(Task task)
   at System.Data.Entity.Utilities.TaskExtensions.CultureAwaiter`1.GetResult()
   at System.Data.Entity.Core.Mapping.Update.Internal.DynamicUpdateCommand.<ExecuteAsync>d__0.MoveNext()
--- End of stack trace from previous location where exception was thrown ---
   at System.Runtime.CompilerServices.TaskAwaiter.ThrowForNonSuccess(Task task)
   at System.Runtime.CompilerServices.TaskAwaiter.HandleNonSuccessAndDebuggerNotification(Task task)
   at System.Data.Entity.Core.Mapping.Update.Internal.UpdateTranslator.<UpdateAsync>d__0.MoveNext()
   --- End of inner exception stack trace ---
   at System.Data.Entity.Core.Mapping.Update.Internal.UpdateTranslator.<UpdateAsync>d__0.MoveNext()
--- End of stack trace from previous location where exception was thrown ---
   at System.Runtime.CompilerServices.TaskAwaiter.ThrowForNonSuccess(Task task)
   at System.Runtime.CompilerServices.TaskAwaiter.HandleNonSuccessAndDebuggerNotification(Task task)
   at System.Data.Entity.Core.Objects.ObjectContext.<ExecuteInTransactionAsync>d__3d`1.MoveNext()
--- End of stack trace from previous location where exception was thrown ---
   at System.Runtime.CompilerServices.TaskAwaiter.ThrowForNonSuccess(Task task)
   at System.Runtime.CompilerServices.TaskAwaiter.HandleNonSuccessAndDebuggerNotification(Task task)
   at System.Data.Entity.Core.Objects.ObjectContext.<SaveChangesToStoreAsync>d__39.MoveNext()
--- End of stack trace from previous location where exception was thrown ---
   at System.Runtime.CompilerServices.TaskAwaiter.ThrowForNonSuccess(Task task)
   at System.Runtime.CompilerServices.TaskAwaiter.HandleNonSuccessAndDebuggerNotification(Task task)
   at System.Data.Entity.SqlServer.DefaultSqlExecutionStrategy.<ExecuteAsyncImplementation>d__9`1.MoveNext()
--- End of stack trace from previous location where exception was thrown ---
   at System.Runtime.CompilerServices.TaskAwaiter.ThrowForNonSuccess(Task task)
   at System.Runtime.CompilerServices.TaskAwaiter.HandleNonSuccessAndDebuggerNotification(Task task)
   at System.Data.Entity.Core.Objects.ObjectContext.<SaveChangesInternalAsync>d__31.MoveNext()
   --- End of inner exception stack trace ---
   at System.Runtime.CompilerServices.TaskAwaiter.ThrowForNonSuccess(Task task)
   at System.Runtime.CompilerServices.TaskAwaiter.HandleNonSuccessAndDebuggerNotification(Task task)
   at System.Runtime.CompilerServices.TaskAwaiter`1.GetResult()
   at XOG.AppCode.BLL.SubCategoryBL.<AddAsync>d__9.MoveNext() in D:\Projects\XOGProject\XOG.API\XOG.API\AppCode\BLL\SubCategoryBL.cs:line 182<br /><br /><strong>Error Details:</strong> <br /><br /><strong>Method Name:</strong> <br /><br /><strong>Source:</strong> <br /><br /><strong>Stack Trace:</strong><br />NA<br /><hr /><br /><h3>Mail Exception</h3><br /><br /><strong>Error Message:</strong> The SMTP host was not specified.<br /><br /><strong>Error Details:</strong> <br /><br /><strong>Method Name:</strong> CheckHostAndPort<br /><br /><strong>Source:</strong> System<br /><br /><strong>Stack Trace:</strong><br />   at System.Net.Mail.SmtpClient.CheckHostAndPort()
   at System.Net.Mail.SmtpClient.Send(MailMessage message)
   at XOG.Helpers.MailHelper.SendUsingSmtp(IdentityMessage message) in D:\Projects\XOGProject\XOG.API\XOG.API\AppCode\Helpers\MailHelper.cs:line 213
   at XOG.Helpers.MailHelper.Send(IdentityMessage message) in D:\Projects\XOGProject\XOG.API\XOG.API\AppCode\Helpers\MailHelper.cs:line 105
   at XOG.Util.ErrorLogger.LogError(Exception ex, DbEntityValidationException e) in D:\Projects\XOGProject\XOG.API\XOG.API\AppCode\Util\ErrorLogger.cs:line 24<hr /><br />
<h3>Exception Generated On 05 अक्तूबर 2021 @ 23:49</h3><br /><br /><strong>Page Location:</strong> /api/subcategory/add<br /><br /><strong>Client IP Address:</strong> 127.0.0.1<br /><br /><strong>Error Message:</strong> Error Adding Sub Category  : 
System.Data.Entity.Infrastructure.DbUpdateException: An error occurred while updating the entries. See the inner exception for details. ---> System.Data.Entity.Core.UpdateException: An error occurred while updating the entries. See the inner exception for details. ---> System.Data.SqlClient.SqlException: The INSERT statement conflicted with the FOREIGN KEY constraint "fk_SubCategory_Category". The conflict occurred in database "xog_db", table "dbo.Categories", column 'Id'.
The statement has been terminated.
   at System.Data.SqlClient.SqlCommand.<>c.<ExecuteDbDataReaderAsync>b__180_0(Task`1 result)
   at System.Threading.Tasks.ContinuationResultTaskFromResultTask`2.InnerInvoke()
   at System.Threading.Tasks.Task.Execute()
--- End of stack trace from previous location where exception was thrown ---
   at System.Runtime.CompilerServices.TaskAwaiter.ThrowForNonSuccess(Task task)
   at System.Runtime.CompilerServices.TaskAwaiter.HandleNonSuccessAndDebuggerNotification(Task task)
   at System.Data.Entity.Utilities.TaskExtensions.CultureAwaiter`1.GetResult()
   at System.Data.Entity.Core.Mapping.Update.Internal.DynamicUpdateCommand.<ExecuteAsync>d__0.MoveNext()
--- End of stack trace from previous location where exception was thrown ---
   at System.Runtime.CompilerServices.TaskAwaiter.ThrowForNonSuccess(Task task)
   at System.Runtime.CompilerServices.TaskAwaiter.HandleNonSuccessAndDebuggerNotification(Task task)
   at System.Data.Entity.Core.Mapping.Update.Internal.UpdateTranslator.<UpdateAsync>d__0.MoveNext()
   --- End of inner exception stack trace ---
   at System.Data.Entity.Core.Mapping.Update.Internal.UpdateTranslator.<UpdateAsync>d__0.MoveNext()
--- End of stack trace from previous location where exception was thrown ---
   at System.Runtime.CompilerServices.TaskAwaiter.ThrowForNonSuccess(Task task)
   at System.Runtime.CompilerServices.TaskAwaiter.HandleNonSuccessAndDebuggerNotification(Task task)
   at System.Data.Entity.Core.Objects.ObjectContext.<ExecuteInTransactionAsync>d__3d`1.MoveNext()
--- End of stack trace from previous location where exception was thrown ---
   at System.Runtime.CompilerServices.TaskAwaiter.ThrowForNonSuccess(Task task)
   at System.Runtime.CompilerServices.TaskAwaiter.HandleNonSuccessAndDebuggerNotification(Task task)
   at System.Data.Entity.Core.Objects.ObjectContext.<SaveChangesToStoreAsync>d__39.MoveNext()
--- End of stack trace from previous location where exception was thrown ---
   at System.Runtime.CompilerServices.TaskAwaiter.ThrowForNonSuccess(Task task)
   at System.Runtime.CompilerServices.TaskAwaiter.HandleNonSuccessAndDebuggerNotification(Task task)
   at System.Data.Entity.SqlServer.DefaultSqlExecutionStrategy.<ExecuteAsyncImplementation>d__9`1.MoveNext()
--- End of stack trace from previous location where exception was thrown ---
   at System.Runtime.CompilerServices.TaskAwaiter.ThrowForNonSuccess(Task task)
   at System.Runtime.CompilerServices.TaskAwaiter.HandleNonSuccessAndDebuggerNotification(Task task)
   at System.Data.Entity.Core.Objects.ObjectContext.<SaveChangesInternalAsync>d__31.MoveNext()
   --- End of inner exception stack trace ---
   at System.Runtime.CompilerServices.TaskAwaiter.ThrowForNonSuccess(Task task)
   at System.Runtime.CompilerServices.TaskAwaiter.HandleNonSuccessAndDebuggerNotification(Task task)
   at System.Runtime.CompilerServices.TaskAwaiter`1.GetResult()
   at XOG.AppCode.BLL.SubCategoryBL.<AddAsync>d__9.MoveNext() in D:\Projects\XOGProject\XOG.API\XOG.API\AppCode\BLL\SubCategoryBL.cs:line 182<br /><br /><strong>Error Details:</strong> <br /><br /><strong>Method Name:</strong> <br /><br /><strong>Source:</strong> <br /><br /><strong>Stack Trace:</strong><br />NA<br /><hr /><br /><h3>Mail Exception</h3><br /><br /><strong>Error Message:</strong> The SMTP host was not specified.<br /><br /><strong>Error Details:</strong> <br /><br /><strong>Method Name:</strong> CheckHostAndPort<br /><br /><strong>Source:</strong> System<br /><br /><strong>Stack Trace:</strong><br />   at System.Net.Mail.SmtpClient.CheckHostAndPort()
   at System.Net.Mail.SmtpClient.Send(MailMessage message)
   at XOG.Helpers.MailHelper.SendUsingSmtp(IdentityMessage message) in D:\Projects\XOGProject\XOG.API\XOG.API\AppCode\Helpers\MailHelper.cs:line 213
   at XOG.Helpers.MailHelper.Send(IdentityMessage message) in D:\Projects\XOGProject\XOG.API\XOG.API\AppCode\Helpers\MailHelper.cs:line 105
   at XOG.Util.ErrorLogger.LogError(Exception ex, DbEntityValidationException e) in D:\Projects\XOGProject\XOG.API\XOG.API\AppCode\Util\ErrorLogger.cs:line 24<hr /><br />
<h3>Exception Generated On 05 अक्तूबर 2021 @ 23:49</h3><br /><br /><strong>Page Location:</strong> /api/subcategory/add<br /><br /><strong>Client IP Address:</strong> 127.0.0.1<br /><br /><strong>Error Message:</strong> Error Adding Sub Category  : 
System.Data.Entity.Infrastructure.DbUpdateException: An error occurred while updating the entries. See the inner exception for details. ---> System.Data.Entity.Core.UpdateException: An error occurred while updating the entries. See the inner exception for details. ---> System.Data.SqlClient.SqlException: The INSERT statement conflicted with the FOREIGN KEY constraint "fk_SubCategory_Category". The conflict occurred in database "xog_db", table "dbo.Categories", column 'Id'.
The statement has been terminated.
   at System.Data.SqlClient.SqlCommand.<>c.<ExecuteDbDataReaderAsync>b__180_0(Task`1 result)
   at System.Threading.Tasks.ContinuationResultTaskFromResultTask`2.InnerInvoke()
   at System.Threading.Tasks.Task.Execute()
--- End of stack trace from previous location where exception was thrown ---
   at System.Runtime.CompilerServices.TaskAwaiter.ThrowForNonSuccess(Task task)
   at System.Runtime.CompilerServices.TaskAwaiter.HandleNonSuccessAndDebuggerNotification(Task task)
   at System.Data.Entity.Utilities.TaskExtensions.CultureAwaiter`1.GetResult()
   at System.Data.Entity.Core.Mapping.Update.Internal.DynamicUpdateCommand.<ExecuteAsync>d__0.MoveNext()
--- End of stack trace from previous location where exception was thrown ---
   at System.Runtime.CompilerServices.TaskAwaiter.ThrowForNonSuccess(Task task)
   at System.Runtime.CompilerServices.TaskAwaiter.HandleNonSuccessAndDebuggerNotification(Task task)
   at System.Data.Entity.Core.Mapping.Update.Internal.UpdateTranslator.<UpdateAsync>d__0.MoveNext()
   --- End of inner exception stack trace ---
   at System.Data.Entity.Core.Mapping.Update.Internal.UpdateTranslator.<UpdateAsync>d__0.MoveNext()
--- End of stack trace from previous location where exception was thrown ---
   at System.Runtime.CompilerServices.TaskAwaiter.ThrowForNonSuccess(Task task)
   at System.Runtime.CompilerServices.TaskAwaiter.HandleNonSuccessAndDebuggerNotification(Task task)
   at System.Data.Entity.Core.Objects.ObjectContext.<ExecuteInTransactionAsync>d__3d`1.MoveNext()
--- End of stack trace from previous location where exception was thrown ---
   at System.Runtime.CompilerServices.TaskAwaiter.ThrowForNonSuccess(Task task)
   at System.Runtime.CompilerServices.TaskAwaiter.HandleNonSuccessAndDebuggerNotification(Task task)
   at System.Data.Entity.Core.Objects.ObjectContext.<SaveChangesToStoreAsync>d__39.MoveNext()
--- End of stack trace from previous location where exception was thrown ---
   at System.Runtime.CompilerServices.TaskAwaiter.ThrowForNonSuccess(Task task)
   at System.Runtime.CompilerServices.TaskAwaiter.HandleNonSuccessAndDebuggerNotification(Task task)
   at System.Data.Entity.SqlServer.DefaultSqlExecutionStrategy.<ExecuteAsyncImplementation>d__9`1.MoveNext()
--- End of stack trace from previous location where exception was thrown ---
   at System.Runtime.CompilerServices.TaskAwaiter.ThrowForNonSuccess(Task task)
   at System.Runtime.CompilerServices.TaskAwaiter.HandleNonSuccessAndDebuggerNotification(Task task)
   at System.Data.Entity.Core.Objects.ObjectContext.<SaveChangesInternalAsync>d__31.MoveNext()
   --- End of inner exception stack trace ---
   at System.Runtime.CompilerServices.TaskAwaiter.ThrowForNonSuccess(Task task)
   at System.Runtime.CompilerServices.TaskAwaiter.HandleNonSuccessAndDebuggerNotification(Task task)
   at System.Runtime.CompilerServices.TaskAwaiter`1.GetResult()
   at XOG.AppCode.BLL.SubCategoryBL.<AddAsync>d__9.MoveNext() in D:\Projects\XOGProject\XOG.API\XOG.API\AppCode\BLL\SubCategoryBL.cs:line 182<br /><br /><strong>Error Details:</strong> <br /><br /><strong>Method Name:</strong> <br /><br /><strong>Source:</strong> <br /><br /><strong>Stack Trace:</strong><br />NA<br /><hr /><br /><h3>Mail Exception</h3><br /><br /><strong>Error Message:</strong> The SMTP host was not specified.<br /><br /><strong>Error Details:</strong> <br /><br /><strong>Method Name:</strong> CheckHostAndPort<br /><br /><strong>Source:</strong> System<br /><br /><strong>Stack Trace:</strong><br />   at System.Net.Mail.SmtpClient.CheckHostAndPort()
   at System.Net.Mail.SmtpClient.Send(MailMessage message)
   at XOG.Helpers.MailHelper.SendUsingSmtp(IdentityMessage message) in D:\Projects\XOGProject\XOG.API\XOG.API\AppCode\Helpers\MailHelper.cs:line 213
   at XOG.Helpers.MailHelper.Send(IdentityMessage message) in D:\Projects\XOGProject\XOG.API\XOG.API\AppCode\Helpers\MailHelper.cs:line 105
   at XOG.Util.ErrorLogger.LogError(Exception ex, DbEntityValidationException e) in D:\Projects\XOGProject\XOG.API\XOG.API\AppCode\Util\ErrorLogger.cs:line 24<hr /><br />
<h3>Exception Generated On 05 अक्तूबर 2021 @ 23:53</h3><br /><br /><strong>Page Location:</strong> /api/productgroup/add<br /><br /><strong>Client IP Address:</strong> 127.0.0.1<br /><br /><strong>Error Message:</strong> Error Adding Product Group  : 
System.Data.Entity.Infrastructure.DbUpdateException: An error occurred while updating the entries. See the inner exception for details. ---> System.Data.Entity.Core.UpdateException: An error occurred while updating the entries. See the inner exception for details. ---> System.Data.SqlClient.SqlException: The INSERT statement conflicted with the FOREIGN KEY constraint "fk_ProductGroup_SubCategories". The conflict occurred in database "xog_db", table "dbo.SubCategories", column 'Id'.
The statement has been terminated.
   at System.Data.SqlClient.SqlCommand.<>c.<ExecuteDbDataReaderAsync>b__180_0(Task`1 result)
   at System.Threading.Tasks.ContinuationResultTaskFromResultTask`2.InnerInvoke()
   at System.Threading.Tasks.Task.Execute()
--- End of stack trace from previous location where exception was thrown ---
   at System.Runtime.CompilerServices.TaskAwaiter.ThrowForNonSuccess(Task task)
   at System.Runtime.CompilerServices.TaskAwaiter.HandleNonSuccessAndDebuggerNotification(Task task)
   at System.Data.Entity.Utilities.TaskExtensions.CultureAwaiter`1.GetResult()
   at System.Data.Entity.Core.Mapping.Update.Internal.DynamicUpdateCommand.<ExecuteAsync>d__0.MoveNext()
--- End of stack trace from previous location where exception was thrown ---
   at System.Runtime.CompilerServices.TaskAwaiter.ThrowForNonSuccess(Task task)
   at System.Runtime.CompilerServices.TaskAwaiter.HandleNonSuccessAndDebuggerNotification(Task task)
   at System.Data.Entity.Core.Mapping.Update.Internal.UpdateTranslator.<UpdateAsync>d__0.MoveNext()
   --- End of inner exception stack trace ---
   at System.Data.Entity.Core.Mapping.Update.Internal.UpdateTranslator.<UpdateAsync>d__0.MoveNext()
--- End of stack trace from previous location where exception was thrown ---
   at System.Runtime.CompilerServices.TaskAwaiter.ThrowForNonSuccess(Task task)
   at System.Runtime.CompilerServices.TaskAwaiter.HandleNonSuccessAndDebuggerNotification(Task task)
   at System.Data.Entity.Core.Objects.ObjectContext.<ExecuteInTransactionAsync>d__3d`1.MoveNext()
--- End of stack trace from previous location where exception was thrown ---
   at System.Runtime.CompilerServices.TaskAwaiter.ThrowForNonSuccess(Task task)
   at System.Runtime.CompilerServices.TaskAwaiter.HandleNonSuccessAndDebuggerNotification(Task task)
   at System.Data.Entity.Core.Objects.ObjectContext.<SaveChangesToStoreAsync>d__39.MoveNext()
--- End of stack trace from previous location where exception was thrown ---
   at System.Runtime.CompilerServices.TaskAwaiter.ThrowForNonSuccess(Task task)
   at System.Runtime.CompilerServices.TaskAwaiter.HandleNonSuccessAndDebuggerNotification(Task task)
   at System.Data.Entity.SqlServer.DefaultSqlExecutionStrategy.<ExecuteAsyncImplementation>d__9`1.MoveNext()
--- End of stack trace from previous location where exception was thrown ---
   at System.Runtime.CompilerServices.TaskAwaiter.ThrowForNonSuccess(Task task)
   at System.Runtime.CompilerServices.TaskAwaiter.HandleNonSuccessAndDebuggerNotification(Task task)
   at System.Data.Entity.Core.Objects.ObjectContext.<SaveChangesInternalAsync>d__31.MoveNext()
   --- End of inner exception stack trace ---
   at System.Runtime.CompilerServices.TaskAwaiter.ThrowForNonSuccess(Task task)
   at System.Runtime.CompilerServices.TaskAwaiter.HandleNonSuccessAndDebuggerNotification(Task task)
   at System.Runtime.CompilerServices.TaskAwaiter`1.GetResult()
   at XOG.AppCode.BLL.ProductGroupBL.<AddAsync>d__9.MoveNext() in D:\Projects\XOGProject\XOG.API\XOG.API\AppCode\BLL\ProductGroupBL.cs:line 182<br /><br /><strong>Error Details:</strong> <br /><br /><strong>Method Name:</strong> <br /><br /><strong>Source:</strong> <br /><br /><strong>Stack Trace:</strong><br />NA<br /><hr /><br /><h3>Mail Exception</h3><br /><br /><strong>Error Message:</strong> The SMTP host was not specified.<br /><br /><strong>Error Details:</strong> <br /><br /><strong>Method Name:</strong> CheckHostAndPort<br /><br /><strong>Source:</strong> System<br /><br /><strong>Stack Trace:</strong><br />   at System.Net.Mail.SmtpClient.CheckHostAndPort()
   at System.Net.Mail.SmtpClient.Send(MailMessage message)
   at XOG.Helpers.MailHelper.SendUsingSmtp(IdentityMessage message) in D:\Projects\XOGProject\XOG.API\XOG.API\AppCode\Helpers\MailHelper.cs:line 213
   at XOG.Helpers.MailHelper.Send(IdentityMessage message) in D:\Projects\XOGProject\XOG.API\XOG.API\AppCode\Helpers\MailHelper.cs:line 105
   at XOG.Util.ErrorLogger.LogError(Exception ex, DbEntityValidationException e) in D:\Projects\XOGProject\XOG.API\XOG.API\AppCode\Util\ErrorLogger.cs:line 24<hr /><br />
